Workbook

Sheet COMPANY
B3: COMPANY NAME: | G3: Shahtaj Sugar Mills Limited:
B13: Industry Sector: | E13: - - - - - - - - - - - - - - - - - - - - - - - - - - - - - - - - - | H13: Sugar
B15: Product we worked on: | E15: - - - - - - - - - - - - - - - - - - - - | H15: Sugar
B17: Last Annual Report: | E17: - - - - - - - - - - - - - - - - - - - - - - - - - - - - - - - - - | H17: 2020-21
B19: Budgeted Year: | E19: - - - - - - - - - - - - - - - - - - - - - - - - - - - - - - - - - | H19: 2021-22

Sheet Rough work
B1: Growth Rate Sales Revenue | H1: Estimated Price for the year 2022 & 2023
C3: 1st | D3: 2nd | E3: 3rd | F3: 4th | G3: yearly | H3: suppose diff values for 2022 yearly | L3: est. price 2022 | M3: production 2022 | O3: price per ton
B4: 2016-17 | C4: 947597 | D4: 2230849 | E4: 1961458 | F4: 667323 | G4: =sum(C4,D4,E4,F4) -> 5807227 | H4: for 4th quarter: | J4: yearly: | K4: also | M4: 81181 | O4: 100344.6
B5: 2017-18 | C5: 1034095 | D5: 1698802 | E5: 1538641 | F5: 606828 | G5: =sum(C5,D5,E5,F5) -> 4878366 | H5: =E9 -> 1825432 | J5: =sum(C9:E9,I5) -> 5456074 | K5: 7100000 | L5: =K5/$M$4 -> 87.458888 | M5: revenue sugar | O5: total Mtones
B6: 2018-19 | C6: 479318 | D6: 1868956 | E6: 1384475 | F6: 876791 | G6: =sum(C6,D6,E6,F6) -> 4609540 | H6: =(E9*F16)+E9 -> 2337909 | J6: =sum(C9:E9,I6) -> 5456074 | K6: =J5 -> 5456074 | L6: =K6/$M$4 -> 67.208756 | M6: 6179526 | O6: ='1. Sales'!H9 -> 84442.403
B7: 2019-20 | C7: 667943 | D7: 1984973 | E7: 876029 | F7: 1010734 | G7: =sum(C7,D7,E7,F7) -> 4539679 | H7: price 2020-21: | J7: =M8 -> 76.120348 | K7: =J6 -> 5456074 | L7: =K7/$M$4 -> 67.208756 | M7: price last year | O7: sales:
B8: 2020-21 | C8: 846402 | D8: 2527974 | E8: 1306572 | F8: 1633330 | G8: =sum(C8,D8,E8,F8) -> 6314278 | H8: inflation percent: | J8: price: | M8: =M6/M4 -> 76.120348 | O8: =O4*O6 -> 8473339138
B9: 2021-22 | C9: 1563349 | D9: 2067293 | E9: 1825432 | F9: 1633330 | G9: =sum(C9,D9,E9,F9) -> 7089404 | H9: 0.156 | J9: =($J$7*$H9)+$J$7 -> 87.995123 | K9: ---------->----------- | L9: =J9 -> 87.995123 | M9: New Price: | N9: =J7*H11+J7 -> 88.794386
B10: Growth Rate | H10: 0.177 | J10: =($J$7*$H10)+$J$7 -> 89.59365 | K10: ---------->----------- | L10: =J10 -> 89.59365 | M10: Infaltion at: | N10: 0.1665
B11: 2016-17 | C11: =(C5/C4)-1 -> 0.09128142 | D11: =(D5/D4)-1 -> -0.2384953 | E11: =(E5/E4)-1 -> -0.21556261 | F11: =(F5/F4)-1 -> -0.090653252 | G11: =(G5/G4)-1 -> -0.15994915 | H11: =average(H9:H10) -> 0.1665 | J11: =($J$7*$H11)+$J$7 -> 88.794386 | K11: ---------->----------- | L11: =J11 -> 88.794386
B12: 2017-18 | C12: =(C6/C5)-1 -> -0.53648553 | D12: =(D6/D5)-1 -> 0.10016117 | E12: =(E6/E5)-1 -> -0.10019621 | F12: =(F6/F5)-1 -> 0.44487565 | G12: =(G6/G5)-1 -> -0.055105746 | H12: 0.1112 | J12: =($J$7*$H12)+$J$7 -> 84.584931 | K12: ---------->----------- | L12: =J12 -> 84.584931
B13: 2018-19 | C13: =(C7/C6)-1 -> 0.39352789 | D13: =(D7/D6)-1 -> 0.062075833 | E13: =(E7/E6)-1 -> -0.36724823 | F13: =(F7/F6)-1 -> 0.15276503 | G13: =(G7/G6)-1 -> -0.015155742 | H13: 0.1282 | J13: =($J$7*$H13)+$J$7 -> 85.878977 | K13: ---------->----------- | L13: =J13 -> 85.878977
B14: 2019-20 | C14: =(C8/C7)-1 -> 0.26717699 | D14: =(D8/D7)-1 -> 0.27355586 | E14: =(E8/E7)-1 -> 0.49147117 | F14: =(F8/F7)-1 -> 0.61598403 | G14: =(G8/G7)-1 -> 0.39090848 | M14: Average price
B15: 2020-21 | C15: =(C9/C8)-1 -> 0.84705258 | D15: =(D9/D8)-1 -> -0.18223328 | E15: =(E9/E8)-1 -> 0.39711551 | I15: Price from market: | L15: 93.5 | M15: (FINAL)
B16: Average | C16: =Average(C11:C15) -> 0.21251067 | D16: =Average(D11:D15) -> 0.0030128571 | E16: =Average(E11:E15) -> 0.041115925 | F16: =Average(F11:F15) -> 0.28074286 | G16: =Average(G11:G15) -> 0.04017446 | J16: average price for 2021 - 22: | L16: =average(L4:L15) -> 83.580385 | M16: Year 2021-22
B17: Growth Rate | J17: Average price using inflation: | L17: =AVERAGE(L9:L11) -> 88.794386 | M17: =N9 -> 88.794386
B18: divide by 2 | C18: =C16/2 -> 0.10625534 | D18: =D16/2 -> 0.0015064285 | E18: =E16/2 -> 0.020557962 | F18: =F16/2 -> 0.14037143 | G18: =G16/2 -> 0.02008723 | J18: Inflation for 2023 estimated at: | L18: 0.1046 | M18: Price chart:
K19: price for 2023: | L19: =(L16*L18)+L16 -> 92.322894 | M19: Ramadan Price | N19: For 3rd | O19: For 4th
J20: Average price using inflation: | L20: =(L17*L18)+L17 -> 98.082279 | M20: =M17+2.21 -> 91.004386 | N20: =M17+0.71 -> 89.504386 | O20: =N20 -> 89.504386
C25: P r o d u c t i o n D a t a | E25: S e a s o n s
E26: 2022 | F26: 2021 | G26: 2020
C28: Start of season: | D28: - - - - - - - - - - - | E28: 18.11.2021 | F28: 15.11.2020 | G28: 30.11.2019
C29: End of season: | D29: - - - - - - - - - - - | E29: 07.03.2022 | F29: 12.03.2021 | G29: 10.03.2020
C30: Number of Days: | D30: - - - - - - - - - - - | E30: ='4. Labour'!E32 -> 109.66667 | F30: 118 | G30: 102
C31: Raw Material:
C32: Sugar Cane Crushed: | D32: - - - - - - - - - - - | E32: ='3. RawMaterial'!H21 -> 782929.74 | F32: 842079 | G32: 630074
C33: Recovery:
C34: Sugar: | D34: - - - - - - - - - - - | E34: ='3. RawMaterial'!E35 -> 0.097866667 | F34: 0.0964 | G34: 0.0941
C35: Molasses: | D35: - - - - - - - - - - - | E35: 0.0437 | F35: 0.0435 | G35: 0.0434
C36: Production:
C37: Sugar: | D37: - - - - - - - - - - - | E37: ='1. Sales'!H9 -> 84442.403 | F37: 81181 | G37: 59204
C38: Molasses: | D38: - - - - - - - - - - - | E38: =(F38*G16)+F38 -> 38063.104 | F38: 36593 | G38: 28800

Sheet 1. Sales
B3: 1) Sales Budget for the year 2021-22 (Oct-Sept)
B5: FOR SUGAR
D6: 1st Quarter | E6: 2st Quarter | F6: 3rd Quarter | G6: 4th Quarter | H6: Yearly
D7: (Oct-Dec) | E7: (Jan-March) | F7: (April-June) | G7: (July-Sept)
B9: Total M.Tons: | D9: ='1. Sales'!H21 -> 12355.354 | E9: ='1. Sales'!H22 -> 30526.15 | F9: ='1. Sales'!H23 -> 16376.661 | G9: ='1. Sales'!H24 -> 25184.238 | H9: =sum(D9:G9) -> 84442.403
B10: Total KG's: | D10: =D9/0.001 -> 12355354 | E10: =E9/0.001 -> 30526150 | F10: =F9/0.001 -> 16376661 | G10: =G9/0.001 -> 25184238 | H10: =H9/0.001 -> 84442403
B12: Price / M.ton:
B13: Price / KG: | D13: ='Rough work'!M17 -> 88.794386 | E13: ='Rough work'!M20 -> 91.004386 | F13: ='Rough work'!N20 -> 89.504386 | G13: ='Rough work'!O20 -> 89.504386 | H13: =AVERAGE(D13:G13) -> 89.701886
B15: Sales (Rs): | D15: =D10*D13 -> 1097086046 | E15: =E10*E13 -> 2778013546 | F15: =F10*F13 -> 1465783020 | G15: =G10*G13 -> 2254099763 | H15: =sum(D15:G15) -> 7594982375
B19: FOR SUGAR (Product) | I19: last year production
B20: quarters | C20: growth rate | D20: revenue 2020-21 | E20: Sales 2021-22 | F20: Price | G20: M.tons | H20: This year | I20: 81181
B21: 1st | C21: ='Rough work'!C16 -> 0.21251067 | D21: ='Rough work'!C8 -> 846402 | E21: =(C21*D21)+D21 -> 1026271.5 | F21: ='Rough work'!$M$17 -> 88.794386 | G21: =E21/F21 -> 11557.842 | H21: =I22/'1. Sales'!J24 -> 12355.354 | I21: This year production:
B22: 2nd | C22: ='Rough work'!D16 -> 0.0030128571 | D22: ='Rough work'!D8 -> 2527974 | E22: =(C22*D22)+D22 -> 2535590.4 | F22: ='Rough work'!$M$17 -> 88.794386 | G22: =E22/F22 -> 28555.751 | H22: =I22/'1. Sales'!J25 -> 30526.15 | I22: =(81181*'Rough work'!G16)+I20 -> 84442.403
B23: 3rd | C23: ='Rough work'!E16 -> 0.041115925 | D23: ='Rough work'!E8 -> 1306572 | E23: =(C23*D23)+D23 -> 1360292.9 | F23: ='Rough work'!$M$17 -> 88.794386 | G23: =E23/F23 -> 15319.582 | H23: =I22/'1. Sales'!J26 -> 16376.661
B24: 4th | C24: ='Rough work'!F16 -> 0.28074286 | D24: ='Rough work'!F8 -> 1633330 | E24: =(C24*D24)+D24 -> 2091875.7 | F24: ='Rough work'!$M$17 -> 88.794386 | G24: =E24/F24 -> 23558.649 | H24: =I22/'1. Sales'!J27 -> 25184.238 | I24: 1 | J24: ='1. Sales'!G25/'1. Sales'!G21 -> 6.8344788
B25: yearly | C25: ='Rough work'!G16 -> 0.04017446 | D25: ='Rough work'!G8 -> 6314278 | E25: =(C25*D25)+D25 -> 6567950.7 | G25: =SUM(G21:G24) -> 78991.824 | H25: =sum(H21:H24) -> 84442.403 | I25: 2 | J25: ='1. Sales'!G25/'1. Sales'!G22 -> 2.7662317
A26: -> | B26: Sugar industry has annually grown by a rate of 4.4% according to the article from Finance Gov. | I26: 3 | J26: ='1. Sales'!G25/'1. Sales'!G23 -> 5.1562648
A27: -> | B27: The 2022/2023 sugarcane harvested area is slightly reduced due to the impacts of the recent flooding in key production areas. | I27: 4 | J27: ='1. Sales'!G25/'1. Sales'!G24 -> 3.3529862
A29: -> | B29: As a result, the 2022/23 cane sugar production forecast is lowered to 7 million tons.
A30: -> | B30: Despite the slight decline in output expected, there will still be an exportable surplus, and the 2022/23 export forecast
B31: remains 1 million tons.
A32: -> | B32: The Federal Bureau of Revenue (FBR) has predicted an increase of 1.5 to 2 million tonnes in sugar production during the
B33: upcoming crushing season, citing better growth of the sugarcane crop due to monsoon rains.

Sheet 2. Production
B3: 2) Production Budget for the year 2021-22 (Oct-Sept)
B5: FOR SUGAR
D6: 1st Quarter | E6: 2st Quarter | F6: 3rd Quarter | G6: 4th Quarter | H6: Yearly
D7: (Oct-Dec) | E7: (Jan-March) | F7: (April-June) | G7: (July-Sept)
B9: Total M.tons: | D9: ='1. Sales'!D9 -> 12355.354 | E9: ='1. Sales'!E9 -> 30526.15 | F9: ='1. Sales'!F9 -> 16376.661 | G9: ='1. Sales'!G9 -> 25184.238 | H9: ='1. Sales'!H9 -> 84442.403
B10: Desired Ending Inventory: | D10: ='2. Production'!D33 -> 3052.615 | E10: ='2. Production'!D34 -> 1637.6661 | F10: ='2. Production'!D35 -> 1637.6661 | G10: ='2. Production'!D36 -> 1235.5354 | H10: ='2. Production'!D37 -> 1235.5354
B11: (Add)
B12: Total Units Required: | D12: =sum(D9:D10) -> 15407.969 | E12: =sum(E9:E10) -> 32163.816 | F12: =sum(F9:F10) -> 18014.327 | G12: =sum(G9:G10) -> 26419.773 | H12: =sum(H9:H10) -> 85677.938
B13: Expected Begininng Inventory: | D13: ='2. Production'!E33 -> 1235.5354 | E13: ='2. Production'!E34 -> 3052.615 | F13: ='2. Production'!E35 -> 1637.6661 | G13: ='2. Production'!E36 -> 2518.4238 | H13: ='2. Production'!E37 -> 8444.2403
B14: (Less)
B15: Units to be Produced: | D15: =D12-D13 -> 14172.433 | E15: =E12-E13 -> 29111.201 | F15: =F12-F13 -> 16376.661 | G15: =G12-G13 -> 23901.35 | H15: =sum(D15:G15) -> 83561.645
B17: Dividing total units in two quarters: | D17: ='2. Production'!$D$29 -> 0.24724757 | E17: ='2. Production'!$D$30 -> 0.75275243
B18: Total units to be produced: | D18: =($H$15*D17) -> 20660.414 | E18: =($H$15*E17) -> 62901.231 | F18: 0 | G18: 0 | H18: =sum(D18:E18) -> 83561.645
B19: (In First 2 Quarters)
B22: FOR PRODUCTION AND RAW MATERIAL
C23: Quaters: | D23: 2020-21 | E23: 2019-20 | F23: 2018-19 | G23: 2017-18
B24: Sugar Produced: | C24: 1st | D24: 22107 | E24: 16615 | F24: 15025 | G24: 21290
C25: 2nd | D25: =81181-D24 -> 59074 | E25: =59204-E24 -> 42589 | F25: =74585-F24 -> 59560 | G25: =90756-G24 -> 69466
C26: yearly | D26: =sum(D24:D25) -> 81181 | E26: =sum(E24:E25) -> 59204 | F26: =sum(F24:F25) -> 74585 | G26: =sum(G24:G25) -> 90756
B27: Quaterly Conversion: | C27: 1st | D27: =(D24/D26) -> 0.27231741 | E27: =(E24/E26) -> 0.28063982 | F27: =(F24/F26) -> 0.20144801 | G27: =(G24/G26) -> 0.23458504
C28: 2nd | D28: =D25/D26 -> 0.72768259 | E28: =E25/E26 -> 0.71936018 | F28: =F25/F26 -> 0.79855199 | G28: =G25/G26 -> 0.76541496
B29: Average Conversion: | C29: 1st | D29: =AVERAGE(D27:G27) -> 0.24724757 | E29: Using an Average break of 25% & 75% for 1st & 2nd Quarter, respectively.
C30: 2nd | D30: =AVERAGE(D28:G28) -> 0.75275243
B32: Inventory for Production: (10 percent) | C32: quarters | D32: Ending | E32: Begining
C33: 1st | D33: ='1. Sales'!H22*10% -> 3052.615 | E33: =10%*'1. Sales'!H21 -> 1235.5354
C34: 2nd | D34: ='1. Sales'!H23*10% -> 1637.6661 | E34: =10%*'1. Sales'!H22 -> 3052.615
C35: 3rd | D35: ='1. Sales'!H23*10% -> 1637.6661 | E35: =10%*'1. Sales'!H23 -> 1637.6661
C36: 4th | D36: ='1. Sales'!H21*10% -> 1235.5354 | E36: =10%*'1. Sales'!H24 -> 2518.4238
C37: yearly | D37: ='1. Sales'!H21*10% -> 1235.5354 | E37: =10%*'1. Sales'!H25 -> 8444.2403
B40: FOR SUGAR CANE
A41: -> | B41: Lets assume the sugar cane prodcution has Decreased: (According to the market)
A42: -> | B42: As the harvesting season is from november to december, all the production is being done in the 1st and in the 2nd
B43: quater, including the purchase of Raw Material (Sugar Cane) that is also being done in the harvesting season.
A44: -> | B44: Seeing that our yearly production of units in 2021-22 is: | E44: ='1. Sales'!H9 -> 84442.403
A45: -> | B45: However this is only the units that we are selling, we are also having a surplus saved up...
A46: -> | B46: This surplus in raw material, depsite the reduction is raw material availibilty, is still more as there will be extra
B47: left over in the ending inventory.
A48: -> | B48: Seeing Note 46, we can understand that raw material supply is short and as a result our prouduction for last year was cut short

Sheet 3. RawMaterial
B3: 3) Direct-Material Budget for the year 2021-22 (Oct-Sept)
B5: FOR SUGAR CANE (Raw Material)
D6: 1st Quarter | E6: 2st Quarter | F6: 3rd Quarter | G6: 4th Quarter | H6: Yearly
D7: (Oct-Dec) | E7: (Jan-March) | F7: (April-June) | G7: (July-Sept)
B9: Sugar to be produced: | D9: ='2. Production'!D15 -> 14172.433 | E9: ='2. Production'!E15 -> 29111.201 | F9: ='2. Production'!F15 -> 16376.661 | G9: ='2. Production'!G15 -> 23901.35 | H9: ='2. Production'!H15 -> 83561.645
B10: Sugar cane recovery rate: | D10: ='3. RawMaterial'!$E$35 -> 0.097866667 | E10: ='3. RawMaterial'!$E$35 -> 0.097866667 | F10: ='3. RawMaterial'!$E$35 -> 0.097866667 | G10: ='3. RawMaterial'!$E$35 -> 0.097866667 | H10: ='3. RawMaterial'!$E$35 -> 0.097866667
B11: (Multiply)
B12: Raw Material Required per unit: | D12: 100 | E12: 100 | F12: 100 | G12: 100 | H12: 100
B13: (Multiply)
B14: Raw material required: | D14: =D9/D10 -> 144813.69 | E14: =E9/E10 -> 297457.78 | F14: =F9/F10 -> 167336.46 | G14: =G9/G10 -> 244223.6 | H14: =H9/H10 -> 853831.52
B15: (For Production)
B16: Desired Ending Inventory: | D16: ='3. RawMaterial'!$D40 -> 29745.778 | E16: ='3. RawMaterial'!$D41 -> 16733.646 | F16: ='3. RawMaterial'!D42 -> 24422.36 | G16: ='3. RawMaterial'!D43 -> 14481.369 | H16: ='3. RawMaterial'!D44 -> 14481.369
B17: (Add)
B18: Total Raw material required: | D18: =sum(D14:D16) -> 174559.47 | E18: =sum(E14:E16) -> 314191.42 | F18: =sum(F14:F16) -> 191758.82 | G18: =sum(G14:G16) -> 258704.97 | H18: =sum(H14:H16) -> 868312.89
B19: Desired Opening Inventory: | D19: ='3. RawMaterial'!E40 -> 14481.369 | E19: ='3. RawMaterial'!E41 -> 29745.778 | F19: ='3. RawMaterial'!E42 -> 16733.646 | G19: ='3. RawMaterial'!E43 -> 24422.36 | H19: ='3. RawMaterial'!E44 -> 85383.152
B20: (Less)
B21: Raw Material to be purchased: | D21: =D18-D19 -> 160078.1 | E21: =E18-E19 -> 284445.65 | F21: =F18-F19 -> 175025.17 | G21: =G18-G19 -> 234282.61 | H21: =H18-H19 -> 782929.74
B23: Cost of Raw Material per unit: | D23: ='3. RawMaterial'!$F$47 -> 5625 | E23: ='3. RawMaterial'!$F$47 -> 5625 | F23: ='3. RawMaterial'!$F$47 -> 5625 | G23: ='3. RawMaterial'!$F$47 -> 5625 | H23: ='3. RawMaterial'!$F$47 -> 5625
B25: Total Cost of Raw Material (Rs): | D25: =D21*D23 -> 9.0043931e+08 | E25: =E21*E23 -> 1600006753 | F25: =F21*F23 -> 9.8451659e+08 | G25: =G21*G23 -> 1317839669 | H25: =H21*H23 -> 4403979794
B27: Dividing total units in First quarter: | D27: 1
B28: Total Cost of Raw Material: | D28: =($H$25*D27) -> 4403979794 | E28: 0 | F28: 0 | G28: 0 | H28: =sum(D28:E29) -> 4403979794
B29: (In First Quarter)
B32: Sugar Recovery rate for the six past years:
B33: 2021 | C33: 2020 | D33: 2019 | E33: 2018 | F33: 2017 | G33: 2016
B34: 0.0964 | C34: 0.0941 | D34: 0.0994 | E34: 0.0965 | F34: 0.1008 | G34: 0.1
B35: Average Sugar Recovery Rate from sugarcane = | E35: =AVERAGE(B34:G34) -> 0.097866667
B37: FOR SUGAR CANE (Raw Material)
C38: Closing and opening inventory rate: | E38: 0.1
B39: quarters | C39: Inventory | D39: Closing inventory | E39: Opening inventory
B40: 1st | C40: ='3. RawMaterial'!D14 -> 144813.69 | D40: =C41*$E$38 -> 29745.778 | E40: =C40*$E$38 -> 14481.369
B41: 2nd | C41: ='3. RawMaterial'!E14 -> 297457.78 | D41: =C42*$E$38 -> 16733.646 | E41: =C41*$E$38 -> 29745.778
B42: 3rd | C42: ='3. RawMaterial'!F14 -> 167336.46 | D42: =C43*$E$38 -> 24422.36 | E42: =C42*$E$38 -> 16733.646
B43: 4th | C43: ='3. RawMaterial'!G14 -> 244223.6 | D43: =C40*$E$38 -> 14481.369 | E43: =C43*$E$38 -> 24422.36
B44: yearly | C44: ='3. RawMaterial'!H14 -> 853831.52 | D44: =C40*$E$38 -> 14481.369 | E44: =C44*$E$38 -> 85383.152
B46: Price of Sugar Cane (Market) | E46: Price per KG | F46: Price per M.ton
B47: Price: | C47: 225 | E47: =C47/C48 -> 5.625 | F47: =C47/C49 -> 5625
B48: Per KG: | C48: 40
B49: Per M.ton: | C49: 0.04
A50: -> | B50: Price of sugar cane is being taken from the market, and for 2022 the price is set to be of 225RS per KG
A51: -> | B51: Furthermore, the purchase of suguarcane is done in the first quarter - hence it is a one time purchase that is being made:

Sheet 4. Labour
B3: 4) Direct-Labour Budget for the year 2021-22 (Oct-Sept)
B5: FOR LABOUR
D6: 1st Quarter | E6: 2st Quarter | F6: 3rd Quarter | G6: 4th Quarter | H6: Yearly
D7: (Oct-Dec) | E7: (Jan-March) | F7: (April-June) | G7: (July-Sept)
B8: Units to be Produced: | D8: ='2. Production'!D15 -> 14172.433 | E8: ='2. Production'!E15 -> 29111.201 | F8: ='2. Production'!F15 -> 16376.661 | G8: ='2. Production'!G15 -> 23901.35 | H8: ='2. Production'!H15 -> 83561.645
B9: Labour Hour Required per Unit: | D9: 24 | E9: 24 | F9: 24 | G9: 24 | H9: 24
B10: (Multiply)
B11: Total Labour Hours: | D11: =D8*D9 -> 340138.4 | E11: =E8*E9 -> 698668.83 | F11: =F8*F9 -> 393039.87 | G11: =G8*G9 -> 573632.39 | H11: =H8*H9 -> 2005479.5
B12: Labour Cost per Hour: | D12: ='4. Labour'!$D$40 -> 134.61538 | E12: ='4. Labour'!$D$40 -> 134.61538 | F12: ='4. Labour'!$D$40 -> 134.61538 | G12: ='4. Labour'!$D$40 -> 134.61538 | H12: ='4. Labour'!$D$40 -> 134.61538
B13: (Multiply)
B14: Total Labour Cost: | D14: =D11*D12 -> 45787861 | E14: =E11*E12 -> 94051573 | F14: =F11*F12 -> 52909213 | G14: =G11*G12 -> 77219745 | H14: =H11*H12 -> 2.6996839e+08
B16: Dividing total units in two quarters: | D16: ='2. Production'!$D$29 -> 0.24724757 | E16: ='2. Production'!$D$30 -> 0.75275243
B17: Total Labour Cost: | D17: =(H14*D16) -> 66749030 | E17: =(H14*E16) -> 2.0321936e+08 | F17: 0 | G17: 0 | H17: =sum(D17:E18) -> 2.6996839e+08
B18: (In First 2 Quarters)
B22: FOR LABOUR
F23: Production Per Day Per KG:
B24: Year: | C24: production | D24: In KGs | E24: Days:
B25: 2022 | C25: ='4. Labour'!H8 -> 83561.645 | D25: =C25/0.001 -> 83561645 | E25: =E32 -> 109.66667 | F25: =D25/E25 -> 761960.29
B26: 2021 | C26: 81180 | D26: =C26/0.001 -> 81180000 | E26: 118 | F26: =D26/E26 -> 687966.1
B27: 2020 | C27: 59204 | D27: =C27/0.001 -> 59204000 | E27: 102 | F27: =D27/E27 -> 580431.37
B28: 2019 | C28: 74585 | D28: =C28/0.001 -> 74585000 | E28: 97 | F28: =D28/E28 -> 768917.53
B29: 2018 | C29: 90756 | D29: =C29/0.001 -> 90756000 | E29: 110 | F29: =D29/E29 -> 825054.55
B30: 2017 | C30: 115754 | D30: =C30/0.001 -> 115754000 | E30: 134 | F30: =D30/E30 -> 863835.82
B31: 2016 | C31: 71599 | D31: =C31/0.001 -> 71599000 | E31: 97 | F31: =D31/E31 -> 738134.02
B32: Average: | D32: =Average(D26:D31) -> 82179667 | E32: =Average(E26:E31) -> 109.66667 | F32: =Average(F26:F31) -> 744056.56
A33: -> | B33: As Sugar cane needs to be processed urgently before it dries out, therefore the factory runs 24/7 to complete its runs and
B34: convert as much sugarcane into the final product as quickly as possibly. Hence, in the first two quarters!
B36: Average Labour Salary per month: | D36: 28000 | E36: (Average salary taken from Paycheck.pk)
B37: number of shifts: | D37: 3
B38: Total salary per month: | D38: =D36*D37 -> 84000
B39: Salary per Day: | D39: =D38/26 -> 3230.7692
B40: Salary per hour: | D40: =D39/24 -> 134.61538

Sheet 5. Manufacturing
B3: 5) Manufacturing-Overhead Budget for the year 2021-22 (Oct-Sept) | J3: FOR VARIABLE MANUFACUTING OVERHEAD
I4: -> | J4: Seeing note number 33, Cost of Sales.
B5: FROM COST OF SALES | I5: -> | J5: Using Growth Rate on Variable Costs = | L5: ='Rough work'!G16 -> 0.04017446
D6: 1st Quarter | E6: 2st Quarter | F6: 3rd Quarter | G6: 4th Quarter | H6: Yearly
D7: (Oct-Dec) | E7: (Jan-March) | F7: (April-June) | G7: (July-Sept) | J7: Dividing into First Two Quarters:
J8: quarters | K8: Division Percent:
B9: VARIABLE COST: | J9: 1st | K9: ='2. Production'!D29 -> 0.24724757
B10: Division: | D10: ='5. Manufacturing'!K9 -> 0.24724757 | E10: ='5. Manufacturing'!K10 -> 0.75275243 | J10: 2nd | K10: ='2. Production'!D30 -> 0.75275243
B11: Cost of Sugar Cane Procurment: | D11: =H11*'5. Manufacturing'!$K$9 -> 1455264198 | E11: =H11*'5. Manufacturing'!$K$10 -> 4430594191 | F11: 0 | G11: 0 | H11: =(5658530000*'5. Manufacturing'!$L$5)+5658530000 -> 5885858389 | I11: -> | J11: As all production is being done in the first two quarters:
B12: Process Materials: | D12: =H12*'5. Manufacturing'!$K$9 -> 15153339 | E12: =H12*'5. Manufacturing'!$K$10 -> 46134781 | F12: 0 | G12: 0 | H12: =(58921000*'5. Manufacturing'!$L$5)+58921000 -> 61288119
B13: Fuel & Power: | D13: =H13*'5. Manufacturing'!$K$9 -> 9093392 | E13: =H13*'5. Manufacturing'!$K$10 -> 27685097 | F13: 0 | G13: 0 | H13: =(35358000*'5. Manufacturing'!$L$5)+35358000 -> 36778489 | J13: FOR FIXED MANUFACUTING OVERHEAD
B14: Stores & Spares Consumed: | D14: =H14*'5. Manufacturing'!$K$9 -> 22594602 | E14: =H14*'5. Manufacturing'!$K$10 -> 68789925 | F14: 0 | G14: 0 | H14: =(87855000*'5. Manufacturing'!$L$5)+87855000 -> 91384527 | I14: -> | J14: Seeing note number 33, Cost of Sales.
B15: Repair & Maintainance: | D15: =H15*'5. Manufacturing'!$K$9 -> 6038343.5 | E15: =H15*'5. Manufacturing'!$K$10 -> 18383913 | F15: 0 | G15: 0 | H15: =(23479000*'5. Manufacturing'!$L$5)+23479000 -> 24422256 | I15: -> | J15: Using Inflatiion Rate on Fixed Costs = | L15: ='Rough work'!H11 -> 0.1665
B16: Other Expenses: | D16: =H16*'5. Manufacturing'!$K$9 -> 2398723.6 | E16: =H16*'5. Manufacturing'!$K$10 -> 7302983.6 | F16: 0 | G16: 0 | H16: =(9327000*'5. Manufacturing'!$L$5)+9327000 -> 9701707.2 | I16: -> | J16: Insurance not being affected by the rate, as insurance is fixed for evey year and month:
I17: -> | J17: For Fixed we will divide the quarters equally, hence dividing the yearly value by 4
B18: TOTAL VARIABLE COST: | D18: =sum(D11:D16) -> 1510542598 | E18: =sum(E11:E16) -> 4598890889 | F18: =sum(F11:F16) -> 0 | G18: =sum(G11:G16) -> 0 | H18: =SUM(H11:H16) -> 6109433487
B20: FIXED COST:
B21: Salaries, Wages & Other Benefits: | D21: =$H21/2 -> 1.4060933e+08 | E21: =$H21/2 -> 1.4060933e+08 | F21: 0 | G21: 0 | H21: =(241079000*'5. Manufacturing'!$L$15)+241079000 -> 2.8121865e+08
B22: Rent, Rate & Taxes: | D22: =$H22/4 -> 332744.12 | E22: =$H22/4 -> 332744.12 | F22: =$H22/4 -> 332744.12 | G22: =$H22/4 -> 332744.12 | H22: =(1141000*'5. Manufacturing'!$L$15)+1141000 -> 1330976.5
B23: Contribution to Provident Fund: | D23: =$H23/4 -> 670154.25 | E23: =$H23/4 -> 670154.25 | F23: =$H23/4 -> 670154.25 | G23: =$H23/4 -> 670154.25 | H23: =(2298000*'5. Manufacturing'!$L$15)+2298000 -> 2680617
B24: Conveyance & Travelling: | D24: =$H24/4 -> 2845093.5 | E24: =$H24/4 -> 2845093.5 | F24: =$H24/4 -> 2845093.5 | G24: =$H24/4 -> 2845093.5 | H24: =(9756000*'5. Manufacturing'!$L$15)+9756000 -> 11380374
B25: Insurance: | D25: =$H25/4 -> 1388250 | E25: =$H25/4 -> 1388250 | F25: =$H25/4 -> 1388250 | G25: =$H25/4 -> 1388250 | H25: 5553000
B27: TOTAL FIXED COST: | D27: =sum(D21:D25) -> 1.4584557e+08 | E27: =sum(E21:E25) -> 1.4584557e+08 | F27: =sum(F21:F25) -> 5236241.9 | G27: =sum(G21:G25) -> 5236241.9 | H27: =SUM(H21:H25) -> 302163621
B29: Total Manufacturing-Ovehead Budget: | D29: =sum(D18,D27) -> 1656388167 | E29: =sum(E18,E27) -> 4744736458 | F29: =sum(F18,F27) -> 5236241.9 | G29: =sum(G18,G27) -> 5236241.9 | H29: =SUM(H18,H27) -> 6411597108

Sheet 6. Admin Expense
B3: 6) Selling, General & Administrative Expense Budget FTY 2021-22 (Oct-Sept) | J3: FOR VARIABLE EXPENSE OVERHEAD
I4: -> | J4: Seeing note number 34 and 35, Distribution Cost and Administrative Expenses
D5: 1st Quarter | E5: 2st Quarter | F5: 3rd Quarter | G5: 4th Quarter | H5: Yearly | I5: -> | J5: Using Growth Rate on Variable Costs = | L5: 0.04017446
D6: (Oct-Dec) | E6: (Jan-March) | F6: (April-June) | G6: (July-Sept)
J7: Dividing into First Two Quarters:
B8: VARIABLE COST: | J8: quarters | K8: Division Percent:
B9: Division: | D9: ='5. Manufacturing'!D10 -> 0.24724757 | E9: ='5. Manufacturing'!E10 -> 0.75275243 | J9: 1st | K9: ='5. Manufacturing'!K9 -> 0.24724757
B10: From Distribution Cost: | J10: 2nd | K10: ='5. Manufacturing'!K10 -> 0.75275243
B11: Sugar Bag Handling: | D11: =$D$9*H11 -> 1395719.2 | E11: =$E$9*H11 -> 4249307.6 | F11: 0 | G11: 0 | H11: =(5427000*'6. Admin Expense'!$L$5)+5427000 -> 5645026.8 | I11: -> | J11: As all production is being done in the first two quarters:
B12: From Aministrative Expenses:
B13: Repair & Maintainance: | D13: =$H13/4 -> 1031333 | E13: =$H13/4 -> 1031333 | F13: =$H13/4 -> 1031333 | G13: =$H13/4 -> 1031333 | H13: =(3966000*'6. Admin Expense'!$L$5)+3966000 -> 4125331.9 | J13: FOR FIXED EXPENSE OVERHEAD
B14: Printing & Stationery: | D14: =$H14/4 -> 704198.11 | E14: =$H14/4 -> 704198.11 | F14: =$H14/4 -> 704198.11 | G14: =$H14/4 -> 704198.11 | H14: =(2708000*'6. Admin Expense'!$L$5)+2708000 -> 2816792.4 | I14: -> | J14: Seeing note number 34 and 35, Distribution Cost and Administrative Expenses
B15: Other Expenses: | D15: =$H15/4 -> 1417497.7 | E15: =$H15/4 -> 1417497.7 | F15: =$H15/4 -> 1417497.7 | G15: =$H15/4 -> 1417497.7 | H15: =(5451000*'6. Admin Expense'!$L$5)+5451000 -> 5669991 | I15: -> | J15: Using Inflation Rate on Fixed Costs = | L15: ='Rough work'!H11 -> 0.1665
I16: -> | J16: For Fixed we will divide the quarters equally, hence dividing the yearly value by 4
B17: TOTAL VARIABLE COST: | D17: =sum(D10:D15) -> 4548748 | E17: =sum(E10:E15) -> 7402336.5 | F17: =sum(F10:F15) -> 3153028.8 | G17: =sum(G10:G15) -> 3153028.8 | H17: =SUM(H10:H15) -> 18257142 | I17: -> | J17: Insurance not being affected by the rate, as insurance is fixed for evey year and month:
B19: FIXED COST:
B20: From Distribution Cost:
B21: Salaries, Wages & Other Benefits: | D21: =$H21/4 -> 1294815 | E21: =$H21/4 -> 1294815 | F21: =$H21/4 -> 1294815 | G21: =$H21/4 -> 1294815 | H21: =(4440000*'6. Admin Expense'!$L$15)+4440000 -> 5179260
B22: Contribution to Provident Fund: | D22: =$H22/4 -> 11956.625 | E22: =$H22/4 -> 11956.625 | F22: =$H22/4 -> 11956.625 | G22: =$H22/4 -> 11956.625 | H22: =(41000*'6. Admin Expense'!$L$15)+41000 -> 47826.5
B23: Insurance: | D23: =$H23/4 -> 871750 | E23: =$H23/4 -> 871750 | F23: =$H23/4 -> 871750 | G23: =$H23/4 -> 871750 | H23: =(3487000) -> 3487000
B24: From Amnistrative Expenses:
B25: Salaries, Wages & Other Benefits: | D25: =$H25/4 -> 58414237 | E25: =$H25/4 -> 58414237 | F25: =$H25/4 -> 58414237 | G25: =$H25/4 -> 58414237 | H25: =('6. Admin Expense'!$L$15*200306000)+200306000 -> 233656949
B26: Contribution to Provident Fund: | D26: =$H26/4 -> 820049.5 | E26: =$H26/4 -> 820049.5 | F26: =$H26/4 -> 820049.5 | G26: =$H26/4 -> 820049.5 | H26: =('6. Admin Expense'!$L$15*2812000)+2812000 -> 3280198
B27: Directors fee: | D27: =$H27/4 -> 361615 | E27: =$H27/4 -> 361615 | F27: =$H27/4 -> 361615 | G27: =$H27/4 -> 361615 | H27: =('6. Admin Expense'!$L$15*1240000)+1240000 -> 1446460
B28: Fuel and power: | D28: =$H28/4 -> 874000.12 | E28: =$H28/4 -> 874000.12 | F28: =$H28/4 -> 874000.12 | G28: =$H28/4 -> 874000.12 | H28: =('6. Admin Expense'!$L$15*2997000)+2997000 -> 3496000.5
B29: Post and Telephone: | D29: =$H29/4 -> 552337.75 | E29: =$H29/4 -> 552337.75 | F29: =$H29/4 -> 552337.75 | G29: =$H29/4 -> 552337.75 | H29: =('6. Admin Expense'!$L$15*1894000)+1894000 -> 2209351
B30: Insurance: | D30: =$H30/4 -> 298332.38 | E30: =$H30/4 -> 298332.38 | F30: =$H30/4 -> 298332.38 | G30: =$H30/4 -> 298332.38 | H30: =('6. Admin Expense'!$L$15*1023000)+1023000 -> 1193329.5
B31: Utilities: | D31: =$H31/4 -> 83988 | E31: =$H31/4 -> 83988 | F31: =$H31/4 -> 83988 | G31: =$H31/4 -> 83988 | H31: =('6. Admin Expense'!$L$15*288000)+288000 -> 335952
B32: Rent, rate and Taxes: | D32: =$H32/4 -> 321079.12 | E32: =$H32/4 -> 321079.12 | F32: =$H32/4 -> 321079.12 | G32: =$H32/4 -> 321079.12 | H32: =('6. Admin Expense'!$L$15*1101000)+1101000 -> 1284316.5
B33: Auditor's Remuneration: | D33: =$H33/4 -> 665196.62 | E33: =$H33/4 -> 665196.62 | F33: =$H33/4 -> 665196.62 | G33: =$H33/4 -> 665196.62 | H33: =('6. Admin Expense'!$L$15*2281000)+2281000 -> 2660786.5
B34: Legal and Professional Charged: | D34: =$H34/4 -> 2849467.9 | E34: =$H34/4 -> 2849467.9 | F34: =$H34/4 -> 2849467.9 | G34: =$H34/4 -> 2849467.9 | H34: =('6. Admin Expense'!$L$15*9771000)+9771000 -> 11397872
B35: Donations: | D35: =$H35/4 -> 166226.25 | E35: =$H35/4 -> 166226.25 | F35: =$H35/4 -> 166226.25 | G35: =$H35/4 -> 166226.25 | H35: =('6. Admin Expense'!$L$15*570000)+570000 -> 664905
B36: Conveyance and Travelling; | D36: =$H36/4 -> 2883004.8 | E36: =$H36/4 -> 2883004.8 | F36: =$H36/4 -> 2883004.8 | G36: =$H36/4 -> 2883004.8 | H36: =('6. Admin Expense'!$L$15*9886000)+9886000 -> 11532019
B38: TOTAL FIXED COST: | D38: =SUM(D21:D23,D25:D36) -> 70468056 | E38: =SUM(E21:E23,E25:E36) -> 70468056 | F38: =SUM(F21:F23,F25:F36) -> 70468056 | G38: =SUM(G21:G23,G25:G36) -> 70468056 | H38: =SUM(H21:H23,H25:H36) -> 281872225
B40: Total Selling, General & Administrative Budget: (RS) | D40: =sum(D17,D38) -> 75016804 | E40: =sum(E17,E38) -> 77870393 | F40: =sum(F17,F38) -> 73621085 | G40: =sum(G17,G38) -> 73621085 | H40: =sum(H17,H38) -> 3.0012937e+08

Sheet 7. Cash Reciept
B3: 7) Cash Reciepts Budget for the year 2021-22 (Oct-Sept)
D5: 1st Quarter | E5: 2st Quarter | F5: 3rd Quarter | G5: 4th Quarter | H5: Yearly
D6: (Oct-Dec) | E6: (Jan-March) | F6: (April-June) | G6: (July-Sept)
B8: FROM SCHEDULE 1: | D8: ='1. Sales'!D15 -> 1097086046 | E8: ='1. Sales'!E15 -> 2778013546 | F8: ='1. Sales'!F15 -> 1465783020 | G8: ='1. Sales'!G15 -> 2254099763 | H8: ='1. Sales'!H15 -> 7594982375
B9: Sales:
B11: Collection of Sale: | D11: =D8*$C$12 -> 8.7766884e+08 | E11: =E8*$C$12 -> 2222410837 | F11: =F8*$C$12 -> 1172626416 | G11: =G8*$C$12 -> 1803279810 | H11: =H8*$C$12 -> 6075985900
B12: Percentage: | C12: 0.8
B13: Collection of Following Sale: | D13: =G8*$C$14 -> 4.0573796e+08 | E13: =D8*$C$14 -> 1.9747549e+08 | F13: =E8*$C$14 -> 5.0004244e+08 | G13: =F8*$C$14 -> 2.6384094e+08 | H13: =sum(D13:G14) -> 1367096827
B14: Percentage: | C14: 0.18
B16: Total Cash Reciepts: (RS) | D16: =SUM(D11:D14) -> 1283406794 | E16: =SUM(E11:E14) -> 2419886325 | F16: =SUM(F11:F14) -> 1672668854 | G16: =SUM(G11:G14) -> 2067120754 | H16: =SUM(H11:H14) -> 7443082727
B18: Uncollectible Accounts: | D18: =D8*$C$19 -> 21941721 | E18: =E8*$C$19 -> 55560271 | F18: =F8*$C$19 -> 29315660 | G18: =G8*$C$19 -> 45081995 | H18: =sum(E18:G19) -> 1.2995793e+08
B19: Percentage: | C19: 0.02

Sheet 8. Cash Disbursement
B3: 8) Cash Disbursement Budget for the year 2021-22 (Oct-Sept)
D5: 1st Quarter | E5: 2st Quarter | F5: 3rd Quarter | G5: 4th Quarter | H5: Yearly
D6: (Oct-Dec) | E6: (Jan-March) | F6: (April-June) | G6: (July-Sept)
B8: Cost of Raw Material: | D8: ='3. RawMaterial'!D25 -> 9.0043931e+08 | E8: ='3. RawMaterial'!E25 -> 1600006753 | F8: ='3. RawMaterial'!F25 -> 9.8451659e+08 | G8: ='3. RawMaterial'!G25 -> 1317839669 | H8: ='3. RawMaterial'!H25 -> 4403979794
B9: (From Schedule 3)
B11: Cash Payment for purchases during the quarter: | D11: =D8*$C$13 -> 5.4026359e+08 | E11: =E8*$C$13 -> 960004052 | F11: =F8*$C$13 -> 5.9070995e+08 | G11: =G8*$C$13 -> 7.907038e+08 | H11: =H8*$C$13 -> 2642387877
B13: Percentage: | C13: 0.6
B14: Cash Payment for purchases during the Prior Quarter: | D14: =G8*$C$15 -> 5.2713587e+08 | E14: =D8*$C$15 -> 3.6017573e+08 | F14: =E8*$C$15 -> 6.400027e+08 | G14: =F8*$C$15 -> 3.9380664e+08 | H14: =sum(D14:G15) -> 1921120930
B15: Percentage: | C15: 0.4
B17: Total Cash Payment for Raw Material Purchases: | D17: =SUM(D12:D15) -> 5.2713587e+08 | E17: =SUM(E12:E15) -> 3.6017573e+08 | F17: =SUM(F12:F15) -> 6.400027e+08 | G17: =SUM(G12:G15) -> 3.9380664e+08 | H17: =SUM(H12:H15) -> 1921120930
B20: OTHER CASH DISBURSEMENT:
B22: FROM SCHEDULE 4:
B23: Total Labour Cost: | D23: ='4. Labour'!D17 -> 66749030 | E23: ='4. Labour'!E17 -> 2.0321936e+08 | F23: 0 | G23: 0 | H23: ='4. Labour'!H17 -> 2.6996839e+08
B25: FROM SCHEDULE 5:
B26: VARIABLE COST:
B27: Cost of Sugar Cane Procurment: | D27: =H27*'5. Manufacturing'!$K$9 -> 1455264198 | E27: =H27*'5. Manufacturing'!$K$10 -> 4430594191 | F27: 0 | G27: 0 | H27: =(5658530000*'5. Manufacturing'!$L$5)+5658530000 -> 5885858389
B28: Process Materials: | D28: =H28*'5. Manufacturing'!$K$9 -> 15153339 | E28: =H28*'5. Manufacturing'!$K$10 -> 46134781 | F28: 0 | G28: 0 | H28: =(58921000*'5. Manufacturing'!$L$5)+58921000 -> 61288119
B29: Fuel & Power: | D29: =H29*'5. Manufacturing'!$K$9 -> 9093392 | E29: =H29*'5. Manufacturing'!$K$10 -> 27685097 | F29: 0 | G29: 0 | H29: =(35358000*'5. Manufacturing'!$L$5)+35358000 -> 36778489
B30: Stores & Spares Consumed: | D30: =H30*'5. Manufacturing'!$K$9 -> 22594602 | E30: =H30*'5. Manufacturing'!$K$10 -> 68789925 | F30: 0 | G30: 0 | H30: =(87855000*'5. Manufacturing'!$L$5)+87855000 -> 91384527
B31: Repair & Maintainance: | D31: =H31*'5. Manufacturing'!$K$9 -> 6038343.5 | E31: =H31*'5. Manufacturing'!$K$10 -> 18383913 | F31: 0 | G31: 0 | H31: =(23479000*'5. Manufacturing'!$L$5)+23479000 -> 24422256
B32: Other Expenses: | D32: =H32*'5. Manufacturing'!$K$9 -> 2398723.6 | E32: =H32*'5. Manufacturing'!$K$10 -> 7302983.6 | F32: 0 | G32: 0 | H32: =(9327000*'5. Manufacturing'!$L$5)+9327000 -> 9701707.2
B34: FIXED COST:
B35: Salaries, Wages & Other Benefits: | D35: =$H35/2 -> 1.4060933e+08 | E35: =$H35/2 -> 1.4060933e+08 | F35: 0 | G35: 0 | H35: =(241079000*'5. Manufacturing'!$L$15)+241079000 -> 2.8121865e+08
B36: Rent, Rate & Taxes: | D36: =$H36/4 -> 332744.12 | E36: =$H36/4 -> 332744.12 | F36: =$H36/4 -> 332744.12 | G36: =$H36/4 -> 332744.12 | H36: =(1141000*'5. Manufacturing'!$L$15)+1141000 -> 1330976.5
B37: Contribution to Provident Fund: | D37: =$H37/4 -> 670154.25 | E37: =$H37/4 -> 670154.25 | F37: =$H37/4 -> 670154.25 | G37: =$H37/4 -> 670154.25 | H37: =(2298000*'5. Manufacturing'!$L$15)+2298000 -> 2680617
B38: Conveyance & Travelling: | D38: =$H38/4 -> 2845093.5 | E38: =$H38/4 -> 2845093.5 | F38: =$H38/4 -> 2845093.5 | G38: =$H38/4 -> 2845093.5 | H38: =(9756000*'5. Manufacturing'!$L$15)+9756000 -> 11380374
B39: Insurance: | D39: =$H39/4 -> 1388250 | E39: =$H39/4 -> 1388250 | F39: =$H39/4 -> 1388250 | G39: =$H39/4 -> 1388250 | H39: 5553000
B41: Total Schedule 5 Budget: | D41: =sum(D27:D32,D35:D39) -> 1656388167 | E41: =sum(E27:E32,E35:E39) -> 4744736458 | F41: =sum(F27:F32,F35:F39) -> 5236241.9 | G41: =sum(G27:G32,G35:G39) -> 5236241.9 | H41: =sum(H27:H32,H35:H39) -> 6411597108
B43: FROM SCHEDULE 6:
B44: VARIABLE COST:
B45: From Distribution Cost:
B46: Sugar Bag Handling: | D46: ='6. Admin Expense'!$D$9*H46 -> 1395719.2 | E46: ='6. Admin Expense'!$E$9*H46 -> 4249307.6 | F46: 0 | G46: 0 | H46: =(5427000*'6. Admin Expense'!$L$5)+5427000 -> 5645026.8
B47: From Aministrative Expenses:
B48: Repair & Maintainance: | D48: =$H48/4 -> 1031333 | E48: =$H48/4 -> 1031333 | F48: =$H48/4 -> 1031333 | G48: =$H48/4 -> 1031333 | H48: =(3966000*'6. Admin Expense'!$L$5)+3966000 -> 4125331.9
B49: Printing & Stationery: | D49: =$H49/4 -> 704198.11 | E49: =$H49/4 -> 704198.11 | F49: =$H49/4 -> 704198.11 | G49: =$H49/4 -> 704198.11 | H49: =(2708000*'6. Admin Expense'!$L$5)+2708000 -> 2816792.4
B50: Other Expenses: | D50: =$H50/4 -> 1417497.7 | E50: =$H50/4 -> 1417497.7 | F50: =$H50/4 -> 1417497.7 | G50: =$H50/4 -> 1417497.7 | H50: =(5451000*'6. Admin Expense'!$L$5)+5451000 -> 5669991
B52: FIXED COST:
B53: From Distribution Cost:
B54: Salaries, Wages & Other Benefits: | D54: =$H54/4 -> 1294815 | E54: =$H54/4 -> 1294815 | F54: =$H54/4 -> 1294815 | G54: =$H54/4 -> 1294815 | H54: =(4440000*'6. Admin Expense'!$L$15)+4440000 -> 5179260
B55: Contribution to Provident Fund: | D55: =$H55/4 -> 11956.625 | E55: =$H55/4 -> 11956.625 | F55: =$H55/4 -> 11956.625 | G55: =$H55/4 -> 11956.625 | H55: =(41000*'6. Admin Expense'!$L$15)+41000 -> 47826.5
...

Sheet 9. Cash Budget
B3: 9) Cash Budget for the year 2021-22 (Oct-Sept) | J3: FOR CASH BUDGET:
J4: Construction of Power Project:
D5: 1st Quarter | E5: 2st Quarter | F5: 3rd Quarter | G5: 4th Quarter | H5: Yearly | I5: -> | J5: Work on the construction of Switch Yard of 132KV is in progress, as written in the Director's Report.
D6: (Oct-Dec) | E6: (Jan-March) | F6: (April-June) | G6: (July-Sept) | I6: -> | J6: From note 6.2, Capital Work-in-Progress:
J7: Year: | K7: Amount | L7: Growth Rate
B8: FROM SCHEDULE 7: | D8: ='7. Cash Reciept'!D16 -> 1283406794 | E8: ='7. Cash Reciept'!E16 -> 2419886325 | F8: ='7. Cash Reciept'!F16 -> 1672668854 | G8: ='7. Cash Reciept'!G16 -> 2067120754 | H8: ='7. Cash Reciept'!H16 -> 7443082727 | J8: 2021 | K8: 479564000 | L8: =(K8/K9)-1 -> 0.015730604
B9: Cash Reciepts: | J9: 2020 | K9: 472137000
B10: (Minus) | K10: 1st | L10: 2nd | M10: 3rd | N10: 4th | O10: yearly
B11: FROM SCHEDULE 8: | D11: ='8. Cash Disbursement'!D73 -> 1731550117 | E11: ='8. Cash Disbursement'!E73 -> 4822751997 | F11: ='8. Cash Disbursement'!F73 -> 79002473 | G11: ='8. Cash Disbursement'!G73 -> 79002473 | H11: ='8. Cash Disbursement'!H73 -> 6712307061 | J11: Construction of Switch Yard: (32MV Power project ) | K11: =$O$11/4 -> 1.2177696e+08 | L11: =$O$11/4 -> 1.2177696e+08 | M11: =$O$11/4 -> 1.2177696e+08 | N11: =$O$11/4 -> 1.2177696e+08 | O11: =(K8*L8)+K8 -> 4.8710783e+08
B12: Cash Disbursements:
B13: Change in cash balance during quarter due to operations: (RS) | D13: =(D8-D11) -> -4.4814332e+08 | E13: =(E8-E11) -> -2402865672 | F13: =(F8-F11) -> 1593666381 | G13: =(G8-G11) -> 1988118280 | H13: =(H8-H11) -> 7.3077567e+08
J14: Cash Balance: | K14: ='9. Cash Budget'!$D$13-K12 -> -4.4814332e+08 | L14: ='9. Cash Budget'!$E$13-L12 -> -2402865672 | M14: ='9. Cash Budget'!$D$13-M12 -> -4.4814332e+08 | N14: ='9. Cash Budget'!$E$13-N12 -> -2402865672 | O14: ='9. Cash Budget'!$D$13-O12 -> -4.4814332e+08
B16: Proceeds from bank loan: | D16: 500000000 | E16: 2500000000 | F16: 0 | G16: 0 | H16: =Sum(D16:E16) -> 3000000000 | I16: -> | J16: INTEREST Rate for Loan 1, December 31st, 2021 for first quarter = | M16: 0.0975
I17: -> | J17: INTEREST Rate for Loan 2, March 31st, 2022 for the second quarter = | M17: 0.1225
B18: Construction of Switch Yard: | D18: =-'9. Cash Budget'!K11 -> -1.2177696e+08 | E18: =-'9. Cash Budget'!L11 -> -1.2177696e+08 | F18: =-'9. Cash Budget'!M11 -> -1.2177696e+08 | G18: =-'9. Cash Budget'!N11 -> -1.2177696e+08 | H18: =-'9. Cash Budget'!O11 -> -4.8710783e+08 | J18: CALCULATION OF INTEREST:
B19: Repayment of principle - bank loan 1: | D19: =-$D$16/4 -> -125000000 | E19: =-$D$16/4 -> -125000000 | F19: =-$D$16/4 -> -125000000 | G19: =-$D$16/4 -> -125000000 | H19: =(D19*4) -> -500000000 | J19: For First Loan: (December 31st)
B20: Repayment of principle - bank loan 2: | D20: 0 | E20: =-$E$16/8 -> -312500000 | F20: =-$E$16/8 -> -312500000 | G20: =-$E$16/8 -> -312500000 | H20: =sum(E20:G20) -> -937500000 | J20: quarters | K20: Unpaid Principle: | L20: Interest rate: | M20: Portion of the year: | N20: Interest Payment:
B21: Interest on Bank Loan 1: | D21: =-('9. Cash Budget'!$N21) -> -12187500 | E21: =-('9. Cash Budget'!$N22) -> -9140625 | F21: =-('9. Cash Budget'!$N23) -> -6093750 | G21: =-('9. Cash Budget'!$N24) -> -3046875 | H21: =-('9. Cash Budget'!$N25) -> -30468750 | J21: 1st | K21: ='9. Cash Budget'!D16 -> 500000000 | L21: =$M$16 -> 0.0975 | M21: 4 | N21: =(K21*L21)/M21 -> 12187500
B22: Interest on Bank Loan 2: | D22: 0 | E22: =-'9. Cash Budget'!N29 -> -38281250 | F22: =-'9. Cash Budget'!N30 -> -33496094 | G22: =-'9. Cash Budget'!N31 -> -28710938 | H22: =-'9. Cash Budget'!N36 -> -1.1005859e+08 | J22: 2nd | K22: =K21+'9. Cash Budget'!E19 -> 375000000 | L22: =$M$16 -> 0.0975 | M22: 4 | N22: =(K22*L22)/M22 -> 9140625
J23: 3rd | K23: =K22+'9. Cash Budget'!F19 -> 250000000 | L23: =$M$16 -> 0.0975 | M23: 4 | N23: =(K23*L23)/M23 -> 6093750
B24: Change in cash balance during the year 2021-2022: | D24: 0 | E24: 0 | F24: 0 | G24: 0 | H24: =H13+H16+H18+H19+H20+H21+H22 -> 1665640491 | J24: 4th | K24: =K23+'9. Cash Budget'!G19 -> 125000000 | L24: =$M$16 -> 0.0975 | M24: 4 | N24: =(K24*L24)/M24 -> 3046875
J25: Yearly | K25: ---------------------------------------------------------------------------------> | N25: =sum(N21:N24) -> 30468750
J26: For Second Loan: (March 31st)
J27: quarters | K27: Unpaid Principle: | L27: Interest rate: | M27: Portion of the year: | N27: Interest Payment:
J28: 1st | K28: ='9. Cash Budget'!E16 -> 2500000000 | L28: =$M$17 -> 0.1225 | M28: 8 | N28: =(K28*L28)/M28 -> 38281250
J29: 2nd | K29: =K28+'9. Cash Budget'!E20 -> 2187500000 | L29: =$M$17 -> 0.1225 | M29: 8 | N29: =(K28*L29)/M29 -> 38281250
J30: 3rd | K30: =K29+'9. Cash Budget'!$F$20 -> 1875000000 | L30: =$M$17 -> 0.1225 | M30: 8 | N30: =(K29*L30)/M30 -> 33496094
J31: 4th | K31: =K30+'9. Cash Budget'!$F$20 -> 1562500000 | L31: =$M$17 -> 0.1225 | M31: 8 | N31: =(K30*L31)/M31 -> 28710938
J32: 1st | K32: =K31+'9. Cash Budget'!$F$20 -> 1250000000 | L32: =$M$17 -> 0.1225 | M32: 8 | N32: =(K31*L32)/M32 -> 23925781
J33: 2nd | K33: =K32+'9. Cash Budget'!$F$20 -> 937500000 | L33: =$M$17 -> 0.1225 | M33: 8 | N33: =(K32*L33)/M33 -> 19140625
J34: 3rd | K34: =K33+'9. Cash Budget'!$F$20 -> 625000000 | L34: =$M$17 -> 0.1225 | M34: 8 | N34: =(K33*L34)/M34 -> 14355469
J35: 4th | K35: =K34+'9. Cash Budget'!$F$20 -> 312500000 | L35: =$M$17 -> 0.1225 | M35: 8 | N35: =(K34*L35)/M35 -> 9570312.5
J36: 3 quarters total | K36: ---------------------------------------------------------------------------------> | N36: =sum(N28:N30) -> 1.1005859e+08

Sheet 10. COGS
B3: 10) Budgeted Schedule for COG Manufactured & Sold FTY 2021-22 (Oct-Sept) | J3: FOR BUDGETED SCHEDULE OF COG MANUFACTURED & SOLD:
I5: -> | J5: From Schedule 3
B6: FROM SCHEDULE 3: | J6: DIRECT MATERIAL Opening and closing inventory in Ruppees:
B7: Direct Material: | L7: KG | M7: Price | N7: Inventory:
C8: Raw Material Inventory: (October 1st) | G8: =N8 -> 4.8028023e+08 | J8: Raw Material Inventory: (Oct 1st) | L8: ='3. RawMaterial'!H19 -> 85383.152 | M8: ='3. RawMaterial'!H23 -> 5625 | N8: =L8*M8 -> 4.8028023e+08
B9: (Add) | C9: Purchases of Raw Material: | G9: ='3. RawMaterial'!H28 -> 4403979794 | J9: Raw Material Inventory: (Sept 30th) | L9: ='3. RawMaterial'!H16 -> 14481.369 | M9: ='3. RawMaterial'!H23 -> 5625 | N9: =L9*M9 -> 81457702
C10: Raw Material Available for Use: | G10: =sum(G8:G9) -> 4884260027
B11: (Minus) | C11: Raw Material Inventory: (September 30th) | G11: =N9 -> 81457702 | I11: -> | J11: From Schedule 2
J12: PRODUCTION Opening and closing inventory in Ruppees:
C13: Direct Material Used: | F13: - - - - - - - - - - - - - - - - - - - - - - - - - - - - | H13: =G10-G11 -> 4802802325 | L13: KG | M13: Price | N13: Inventory:
B14: FROM SCHEDULE 4: | D14: Direct Labour: | H14: ='4. Labour'!H17 -> 2.6996839e+08 | J14: Sugar Inventory: (Oct 1st) | L14: ='2. Production'!H13 -> 8444.2403 | M14: ='1. Sales'!H13 -> 89.701886 | N14: =L14*M14 -> 757464.28
B15: FROM SCHEDULE 5: | D15: Manufacturing Overhead: | H15: =sum('5. Manufacturing'!H12:H16,'5. Manufacturing'!H22:H25) -> 244520066 | J15: Sugar Inventory: (Sept 30th) | L15: ='2. Production'!H10 -> 1235.5354 | M15: ='1. Sales'!H13 -> 89.701886 | N15: =L15*M15 -> 110829.85
D16: (Add)
C17: Total Manufacturing Cost: | F17: - - - - - - - - - - - - - - - - - - - - - - - - - - - - | H17: =sum(H13:H15) -> 5317290784
B19: (Add) | C19: Work-in-Process Inventory: (October 1st) | H19: 0
H20: =H17+H19 -> 5317290784
B21: (Minus) | C21: Work-in-Process Inventory: (September 30st) | H21: 0
C22: Cost of Goods Manufactured: | F22: - - - - - - - - - - - - - - - - - - - - - - - - - - - - | H22: =H20-H21 -> 5317290784
B24: FROM SCHEDULE 2:
B25: (Add) | C25: Finished Goods Inventory: (October 1st) | H25: =N14 -> 757464.28
C26: Cost of Goods Available for Sale: | F26: - - - - - - - - - - - - - - - - - - - - - - - - - - - - | H26: =H22+H25 -> 5318048248
B27: (Minus) | C27: Finished Goods Inventory: (September 30th) | H27: =N15 -> 110829.85
C29: Cost of Goods Sold: | F29: - - - - - - - - - - - - - - - - - - - - - - - - - - - - | H29: =H26-H27 -> 5317937418

Sheet 11. Income Statement
B3: 11) Budgeted Income Statement for the year 2021-22 (Oct-Sept)
B6: FROM SCHEDULE 1:
C7: Sales Revenue: | G7: ='1. Sales'!H15 -> 7594982375
B8: FROM SCHEDULE 10:
B9: (Minus) | C9: Cost of Goods Sold: | G9: ='10. COGS'!H29 -> 5317937418
D10: Gross Margin: | F10: - - - - - - - - - - - - | G10: =G7-G9 -> 2277044957
B11: Other Expenses:
B12: FROM SCHEDULE 6: | D12: Selling & Administrative Expenses: | G12: ='6. Admin Expense'!H40 -> 3.0012937e+08
B13: FROM SCHEDULE 7: | D13: Uncollectible accounts expense: | G13: ='7. Cash Reciept'!H18 -> 1.2995793e+08
B14: FROM SCHEDULE 9: | D14: Interest expense - Loan 1: | G14: ='9. Cash Budget'!N25 -> 30468750
D15: Interest expense - Loan 2: | G15: ='9. Cash Budget'!N36 -> 1.1005859e+08
C16: Total Other Expenses: | F16: - - - - - - - - - - - - | G16: =SUM(G12:H15) -> 5.7061464e+08
E18: NET INCOME: | F18: - - - - - - - - - - - - | G18: =G10-G16 -> 1706430319

Sheet 12. Cash Flow
B3: 12) Budgeted Statement of Cash Flow for the year 2021-22 (Oct-Sept)
B6: Cash Flow from Operating Activities:
B7: FROM SCHEDULE 7: | D7: Cash Reciepts from Customers: | H7: ='7. Cash Reciept'!H16 -> 7443082727
D9: Cash Payments made:
B10: FROM SCHEDULE 8: | D10: To suppliers of Raw Material: | G10: ='8. Cash Disbursement'!H17 -> 1921120930
B11: FROM SCHEDULE 4: | D11: For Direct Labour: | G11: ='4. Labour'!H17 -> 2.6996839e+08
B12: FROM SCHEDULE 5: | D12: For Manufacturing-Overhead Expense: | G12: ='5. Manufacturing'!H29 -> 6411597108
B13: FROM SCHEDULE 6: | D13: For Administrative Expenses: | G13: ='6. Admin Expense'!H40 -> 3.0012937e+08
B14: FROM SCHEDULE 9: | D14: For Interest: | G14: =SUM('9. Cash Budget'!N25,'9. Cash Budget'!N36) -> 1.4052734e+08
D16: Total Cash Payment: | H16: =sum(G10:G14) -> 9043343142
D17: Net Cash from Operating Activites: | F17: - - - - - - - - - - - - - - - - - - - - - - - - - - - - | H17: =H7-H16 -> -1600260414
B19: Cash Flow from Investing Activities:
B20: FROM SCHEDULE 9: | D20: Construction of Switch Yard: | G20: ='9. Cash Budget'!H18 -> -4.8710783e+08
D21: Net Cash from Investing Activites: | F21: - - - - - - - - - - - - - - - - - - - - - - - - - - - - | H21: =G20 -> -4.8710783e+08
B23: Cash Flow from Financing Activities:
B24: FROM SCHEDULE 9: | D24: Principle of Bank Loan: | G24: =sum('9. Cash Budget'!E16,'9. Cash Budget'!D16) -> 3000000000
B25: FROM SCHEDULE 9: | D25: Repayment of Bank Loan: | G25: =sum('9. Cash Budget'!H21,'9. Cash Budget'!H22) -> -1.4052734e+08
D26: Net Cash from Financing Activites: | F26: - - - - - - - - - - - - - - - - - - - - - - - - - - - - | H26: =G24+G25 -> 2859472656
C28: Net Increase/Decrease in Cash and Cash Equilivants: | H28: =H17+H21+H26 -> 7.7210441e+08
C29: Change in cash - Beginning of the year: | H29: 52962000
C30: Balance in Cash Equilivants - End of the Year: | F30: - - - - - - - - - - - - - - - - - - - - - - - - - - - - | H30: =H28+H29 -> 8.2506641e+08

Sheet 13. Balance Sheet
B3: 13) Budgeted Balance Sheet for the year 2021-22 (Oct-Sept)
B6: ASSETS | J6: Values From 2021
B7: Current Assets:
B8: FROM SCHEDULE 9: | D8: Cash: | H8: ='9. Cash Budget'!H24 -> 1665640491 | J8: .
B9: FROM SCHEDULE 7: | D9: Accounts Recievables: | H9: =18%*'7. Cash Reciept'!G8 -> 4.0573796e+08
D10: Bank Guarantee Margin: | H10: =J10 -> 13600000 | J10: 13600000
B11: FROM SCHEDULE 10: | D11: Raw Material: | G11: ='10. COGS'!G11 -> 81457702
B12: FROM SCHEDULE 10: | D12: Finished Goods: | G12: ='10. COGS'!H27 -> 110829.85 | J12: .
E13: Loans: | G13: ='9. Cash Budget'!K31 -> 1562500000 | J13: .
D14: Total Inventory: | H14: =sum(G11:G13) -> 1644068531 | J14: .
D15: Total Current Assets: | F15: - - - - - - - - - - - - - - - - - - - - - - - - - - - - | H15: =SUM(H8:H14) -> 3729046980 | J15: .
B16: Non-Current Assets:
D17: Investment in Associate: | G17: =L23 -> 1.7562306e+08 | J17: 168840000 | K17: Investment in Associate:
K18: 2018 | L18: 2019 | M18: 2020 | N18: 2021
D19: Total Non-Current Assets: | F19: - - - - - - - - - - - - - - - - - - - - - - - - - - - - | H19: =sum(G17:G18) -> 1.7562306e+08 | J19: . | K19: 116039000 | L19: 139023000 | M19: 140373000 | N19: 168840000
B20: Long Lived Assets: | K20: rate: | L20: =L19/K19-1 -> 0.19807134 | M20: =M19/L19-1 -> 0.0097106234 | N20: =N19/M19-1 -> 0.20279541
B21: FROM SCHEDULE 9: | D21: Building: | G21: =J21 -> 23732000 | J21: 23732000 | K21: Average: | L21: =Average(L20:N20) -> 0.13685912
D22: Equipment: | G22: =J22 -> 1441051000 | J22: 1441051000 | K22: investment in 2022: | L22: =(N19*L21)+N19 -> 1.9194729e+08
B23: FROM SCHEDULE 5: | D23: (Accumulated Depreciation) | K23: investment in 2022: | L23: =(N19*'Rough work'!G16)+N19 -> 1.7562306e+08 | M23: with 4 percent growth rate
B24: (Minus) | D24: On Building: | G24: =-N26 -> -7911000 | J24: .
E25: On Equipment: | G25: =-N28 -> -1073022000 | J25: . | K25: Acc .Depreciation: | L25: 2020 | M25: 44390 | N25: 2022
D26: Net Accumulated Depreciation: | F26: - - - - - - - - - - - - - - - - - - - - - - - - - - - - | H26: =(G21+G22)+(G24+G25) -> 383850000 | J26: . | K26: Building: | L26: 2637000 | M26: =L26+L26 -> 5274000 | N26: =M26+L26 -> 7911000
J27: . | K27: Charge of the year: | L27: 2637000
D28: Total Assets: | F28: - - - - - - - - - - - - - - - - - - - - - - - - - - - - | H28: =sum(H15,H19,H26) -> 4288520036 | J28: . | K28: Equipment: | L28: 1032586000 | M28: =L28+L29 -> 1052804000 | N28: =M28+L29 -> 1073022000
J29: . | K29: Charge of the year: | L29: 20218000
B30: LIABILITIES & OWNER'S EQUITY | J30: .
B31: Current Liabilities: | J31: .
B32: FROM SCHEDULE 8: | D32: Accounts Payable: | G32: ='8. Cash Disbursement'!G8*'8. Cash Disbursement'!C15 -> 5.2713587e+08 | J32: .
D33: Provision for Taxation: | G33: 79950000
D34: Unclaimed Divident: | G34: =J34 -> 1953000 | J34: 1953000
D35: Current maturity of lease liabilities: | G35: 4312000
D36: Total Current Liabilites: | F36: - - - - - - - - - - - - - - - - - - - - - - - - - - - - | H36: =sum(G32:G35) -> 6.1335087e+08
J37: .
B38: Non-Current Liabilities:
D39: Loan from Associates: | G39: 110000000
D40: Deferred Tax: | G40: 26127849 | J40: 28250000
D41: Total Non-Current Liabilities: | F41: - - - - - - - - - - - - - - - - - - - - - - - - - - - - | H41: =sum(F39:G40) -> 136127849
B43: Long-Term Liabilities: | J43: .
D45: Notes Payable: | F45: ='9. Cash Budget'!K31 -> 1562500000 | J45: .
D46: Total long-Term Liabilities: | F46: - - - - - - - - - - - - - - - - - - - - - - - - - - - - | H46: =sum(F44:G45) -> 1562500000 | J46: .
...
